Traceback (most recent call last):
  File "CreatePointCloud.py", line 215, in <module>
    wall_distance = np.array(f['Base'][field2Read]['PointData']['Wall_Distance'][' data'])
  File "h5py/_objects.pyx", line 54, in h5py._objects.with_phil.wrapper
  File "h5py/_objects.pyx", line 55, in h5py._objects.with_phil.wrapper
  File "/home/pagaf/.local/lib/python3.8/site-packages/h5py/_hl/group.py", line 357, in __getitem__
    oid = h5o.open(self.id, self._e(name), lapl=self._lapl)
  File "h5py/_objects.pyx", line 54, in h5py._objects.with_phil.wrapper
  File "h5py/_objects.pyx", line 55, in h5py._objects.with_phil.wrapper
  File "h5py/h5o.pyx", line 241, in h5py.h5o.open
KeyError: "Unable to synchronously open object (object 'Wall_Distance' doesn't exist)"
